<mujoco model="dual_ur5e">
  <compiler angle="radian" />

  <default>
    <default class="ur5e">
      <material specular="0.5" shininess="0.25" />
      <joint axis="0 1 0" range="-6.28319 6.28319" armature="0.1" />
      <general gaintype="fixed" biastype="affine" ctrlrange="-6.2831 6.2831" gainprm="2000" biasprm="0 -2000 -400" forcerange="-150 150" />
      <default class="size3">
        <default class="size3_limited">
          <joint range="-3.1415 3.1415" />
          <general ctrlrange="-3.1415 3.1415" />
        </default>
      </default>
      <default class="size1">
        <general gainprm="500" biasprm="0 -500 -100" forcerange="-28 28" />
      </default>
      <default class="visual">
        <geom type="mesh" contype="0" conaffinity="0" group="2" />
      </default>
      <default class="collision">
        <geom type="capsule" group="3" />
        <default class="eef_collision">
          <geom type="cylinder" />
        </default>
      </default>
      <site size="0.001" rgba="0.5 0.5 0.5 0.3" group="4" />
    </default>
  </default>

  <asset>
    <material class="ur5e" name="black" rgba="0.033 0.033 0.033 1" />
    <material class="ur5e" name="jointgray" rgba="0.278 0.278 0.278 1" />
    <material class="ur5e" name="linkgray" rgba="0.82 0.82 0.82 1" />
    <material class="ur5e" name="urblue" rgba="0.49 0.678 0.8 1" />
  </asset>

  <worldbody>
    <body name="dual_base">
      <inertial pos="0 0 0" mass="0.001" diaginertia="0.001 0.001 0.001" />

      <!-- Left Arm -->
      <light name="spotlight_left" mode="targetbodycom" target="wrist_2_link_left" pos="0 -1 2" />
      <body name="base_left" pos="0 0.4 0" childclass="ur5e">
        <inertial mass="4.0" pos="0 0 0" diaginertia="0.00443333156 0.00443333156 0.0072" />
        <body name="shoulder_link_left" pos="0 0 0.163">
          <inertial mass="3.7" pos="0 0 0" diaginertia="0.0102675 0.0102675 0.00666" />
          <joint name="shoulder_pan_joint_left" class="size3" axis="0 0 1" />
          <body name="upper_arm_link_left" pos="0 0.138 0" quat="1 0 1 0">
            <inertial mass="8.393" pos="0 0 0.2125" diaginertia="0.133886 0.133886 0.0151074" />
            <joint name="shoulder_lift_joint_left" class="size3" />
            <body name="forearm_link_left" pos="0 -0.131 0.425">
              <inertial mass="2.275" pos="0 0 0.196" diaginertia="0.0311796 0.0311796 0.004095" />
              <joint name="elbow_joint_left" class="size3_limited" />
              <body name="wrist_1_link_left" pos="0 0 0.392" quat="1 0 1 0">
                <inertial mass="1.219" pos="0 0.127 0" diaginertia="0.0025599 0.0025599 0.0021942" />
                <joint name="wrist_1_joint_left" class="size1" />
                <body name="wrist_2_link_left" pos="0 0.127 0">
                  <inertial mass="1.219" pos="0 0 0.1" diaginertia="0.0025599 0.0025599 0.0021942" />
                  <joint name="wrist_2_joint_left" axis="0 0 1" class="size1" />
                  <body name="wrist_3_link_left" pos="0 0 0.1">
                    <inertial mass="0.1889" pos="0 0.0771683 0" quat="1 0 0 1" diaginertia="0.000132134 9.90863e-05 9.90863e-05" />
                    <joint name="wrist_3_joint_left" class="size1" />
                    <site name="EE_left" pos="0 0.25 0" euler="1.57079 0 -1.57079" size="0.01" />
                  </body>
                </body>
              </body>
            </body>
          </body>
        </body>
      </body>

      <!-- Right Arm -->
      <light name="spotlight_right" mode="targetbodycom" target="wrist_2_link_right" pos="0 -1 2" />
      <body name="base_right" pos="0 -0.4 0" childclass="ur5e">
        <inertial mass="4.0" pos="0 0 0" diaginertia="0.00443333156 0.00443333156 0.0072" />
        <body name="shoulder_link_right" pos="0 0 0.163">
          <inertial mass="3.7" pos="0 0 0" diaginertia="0.0102675 0.0102675 0.00666" />
          <joint name="shoulder_pan_joint_right" class="size3" axis="0 0 1" />
          <body name="upper_arm_link_right" pos="0 0.138 0" quat="1 0 1 0">
            <inertial mass="8.393" pos="0 0 0.2125" diaginertia="0.133886 0.133886 0.0151074" />
            <joint name="shoulder_lift_joint_right" class="size3" />
            <body name="forearm_link_right" pos="0 -0.131 0.425">
              <inertial mass="2.275" pos="0 0 0.196" diaginertia="0.0311796 0.0311796 0.004095" />
              <joint name="elbow_joint_right" class="size3_limited" />
              <body name="wrist_1_link_right" pos="0 0 0.392" quat="1 0 1 0">
                <inertial mass="1.219" pos="0 0.127 0" diaginertia="0.0025599 0.0025599 0.0021942" />
                <joint name="wrist_1_joint_right" class="size1" />
                <body name="wrist_2_link_right" pos="0 0.127 0">
                  <inertial mass="1.219" pos="0 0 0.1" diaginertia="0.0025599 0.0025599 0.0021942" />
                  <joint name="wrist_2_joint_right" axis="0 0 1" class="size1" />
                  <body name="wrist_3_link_right" pos="0 0 0.1">
                    <inertial mass="0.1889" pos="0 0.0771683 0" quat="1 0 0 1" diaginertia="0.000132134 9.90863e-05 9.90863e-05" />
                    <joint name="wrist_3_joint_right" class="size1" />
                    <site name="EE_right" pos="0 0.25 0" euler="1.57079 0 -1.57079" size="0.01" />
                  </body>
                </body>
              </body>
            </body>
          </body>
        </body>
      </body>
    </body>
  </worldbody>

  <actuator>
    <!-- Left Arm Actuators -->
    <general class="size3" name="shoulder_pan_left" joint="shoulder_pan_joint_left" />
    <general class="size3" name="shoulder_lift_left" joint="shoulder_lift_joint_left" />
    <general class="size3_limited" name="elbow_left" joint="elbow_joint_left" />
    <general class="size1" name="wrist_1_left" joint="wrist_1_joint_left" />
    <general class="size1" name="wrist_2_left" joint="wrist_2_joint_left" />
    <general class="size1" name="wrist_3_left" joint="wrist_3_joint_left" />

    <!-- Right Arm Actuators -->
    <general class="size3" name="shoulder_pan_right" joint="shoulder_pan_joint_right" />
    <general class="size3" name="shoulder_lift_right" joint="shoulder_lift_joint_right" />
    <general class="size3_limited" name="elbow_right" joint="elbow_joint_right" />
    <general class="size1" name="wrist_1_right" joint="wrist_1_joint_right" />
    <general class="size1" name="wrist_2_right" joint="wrist_2_joint_right" />
    <general class="size1" name="wrist_3_right" joint="wrist_3_joint_right" />
  </actuator>

  <keyframe>
    <key name="home" qpos="0 -1.5708 0 -1.5708 0 0 0 -1.5708 0 -1.5708 0 0" />
    <key name="standby1" qpos="3.1415926 -1.5708 -1.5708 -1.5708 1.5708 0 3.1415926 -1.5708 -1.5708 -1.5708 1.5708 0" />
    <key name="standby2" qpos="0 -1.5708 1.5708 -1.5708 -1.5708 0 0 -1.5708 1.5708 -1.5708 -1.5708 0" />
  </keyframe>

</mujoco>
