<?xml version="1.0" encoding="utf-8"?>
<!-- This URDF was automatically created by SolidWorks to URDF Exporter! Originally created by Stephen Brawner (brawner@gmail.com) 
     Commit Version: 1.6.0-4-g7f85cfe  Build Version: 1.6.7995.38578
     For more information, please see http://wiki.ros.org/sw_urdf_exporter -->
<robot
  name="oneLink">
  <link
    name="base">
    <inertial>
      <origin
        xyz="0.017607 2.0762E-05 -0.057369"
        rpy="0 0 0" />
      <mass
        value="0.26056" />
      <inertia
        ixx="0.00091757"
        ixy="3.9561E-08"
        ixz="-0.00010931"
        iyy="0.0005816"
        iyz="2.9483E-08"
        izz="0.00050013" />
    </inertial>
    <visual>
      <origin
        xyz="0 0 0"
        rpy="0 0 0" />
      <geometry>
        <mesh
          filename="../assets/base.STL" />
      </geometry>
      <material
        name="">
        <color
          rgba="0.75294 0.75294 0.75294 1" />
      </material>
    </visual>
    <collision>
      <origin
        xyz="0 0 0"
        rpy="0 0 0" />
      <geometry>
        <mesh
          filename="../assets/base.STL" />
      </geometry>
    </collision>
  </link>
  <joint
    name="Rx"
    type="revolute">
    <origin
      xyz="0.0426 0 0"
      rpy="0 0 0" />
    <parent
      link="base" />
    <child
      link="link1" />
    <axis
      xyz="1 0 0" />
    <limit
      lower="-6.2832"
      upper="6.2832"
      effort="100"
      velocity="10" />
  </joint>
  <link
    name="link1">
    <inertial>
      <origin
        xyz="0 0 -0.208"
        rpy="0 0 0" />
      <mass
        value="1.22" />
      <inertia
        ixx="0.044414947"
        ixy="0"
        ixz="-0.0016"
        iyy="0.05023764"
        iyz="0"
        izz="0.00702564" />
    </inertial>
    <visual>
      <origin
        xyz="0 0 0"
        rpy="0 0 0" />
      <geometry>
        <mesh
          filename="../assets/link1.STL" />
      </geometry>
      <material
        name="">
        <color
          rgba="0.75294 0.75294 0.75294 1" />
      </material>
    </visual>
    <collision>
      <origin
        xyz="0 0 0"
        rpy="0 0 0" />
      <geometry>
        <mesh
          filename="../assets/link1.STL" />
      </geometry>
    </collision>
  </link>
  <!-- <joint
    name="Rx"
    type="revolute">
    <origin
      xyz="0.0426 0 0"
      rpy="0 0 0" />
    <parent
      link="base" />
    <child
      link="link1" />
    <axis
      xyz="1 0 0" />
    <limit
      lower="0"
      upper="0"
      effort="0"
      velocity="0" />
  </joint> -->
</robot>