<mujoco model="dual_piper">
  <compiler angle="radian" />

  <default>
    <default class="piper">
      <joint frictionloss="0.3" armature="0.005" />
      <position inheritrange="1" forcerange="-100 100" />
      <default class="finger">
        <joint frictionloss="0" type="slide" />
        <position forcerange="-10 10" />
      </default>
      <default class="visual">
        <geom group="2" type="mesh" contype="0" conaffinity="0" density="0" />
      </default>
      <default class="collision">
        <geom group="3" type="capsule" />
      </default>
    </default>
  </default>

  <worldbody>
    <body name="dual_base">
      <inertial pos="0 0 0" mass="0.001" diaginertia="0.001 0.001 0.001" />

      <!-- Left Arm -->
      <body name="base_link_left" pos="0 0.3 0" childclass="piper" gravcomp="1">
        <inertial pos="-0.00979275 1.82906e-06 0.04101" quat="0.692988 -0.137524 -0.137826 0.69416" mass="0.162549" diaginertia="0.000269445 0.000227478 0.000221437" />
        <body name="link1_left" pos="0 0 0.123" quat="0.707105 0 0 -0.707108" gravcomp="1">
          <inertial pos="0.00131676 0.000310289 -0.00922875" quat="0.557105 0.432155 0.377373 0.600388" mass="0.097868" diaginertia="9.25942e-05 8.3083e-05 7.69469e-05" />
          <joint name="joint1_left" axis="0 0 1" range="-2.618 2.618" />
          <body name="link2_left" quat="0.499998 0.5 -0.500002 -0.5" gravcomp="1">
            <inertial pos="0.148794 -0.00242027 0.00175155" quat="-0.0249063 0.70684 0.00803509 0.706889" mass="0.290889" diaginertia="0.00177549 0.00173142 0.00014552" />
            <joint name="joint2_left" axis="0 0 1" range="0 3.14" />
            <body name="link3_left" pos="0.28358 0.028726 0" quat="0.998726 0 0 0.0504536" gravcomp="1">
              <inertial pos="-0.0996835 0.0349477 0.000508026" quat="0.0777021 0.702287 -0.0990541 0.700674" mass="0.290848" diaginertia="0.000241946 0.000222224 0.000100384" />
              <joint name="joint3_left" pos="0 0 0" axis="0 0 1" range="-2.697 0" />
              <body name="link4_left" pos="-0.24221 0.068514 0" quat="0.544767 -0.544769 -0.450809 0.450808" gravcomp="1">
                <inertial pos="0.000276465 -0.00102804 -0.00472831" quat="0.492305 0.505285 0.503294 0.499017" mass="0.127087" diaginertia="4.87057e-05 4.10595e-05 3.82001e-05" />
                <joint name="joint4_left" axis="0 0 1" range="-1.832 1.832" />
                <body name="link5_left" quat="0.707105 0.707108 0 0" gravcomp="1">
                  <inertial pos="8.82262e-05 0.0566829 -0.0019612" quat="0.507447 0.490986 0.506887 0.494466" mass="0.144711" diaginertia="0.001 0.001 0.001" />
                  <joint name="joint5_left" axis="0 0 1" range="-1.22 1.22" />
                  <body name="link6_left" pos="0 0.091 0.0014165" quat="0 0 -0.707105 -0.707108" gravcomp="1">
                    <inertial pos="0.0010312 0.0121761 0.0315481" quat="0.0230402 0.707091 0.0373344 0.70576" mass="1.2" diaginertia="0.001 0.001 0.001" />
                    <joint name="joint6_left" axis="0 0 1" range="-3.14 3.14" />
                    <site name="EE_left" pos="0.00 0.0 0.13503" euler="3.1415926 0 3.1415926" size="0.001" />
                  </body>
                </body>
              </body>
            </body>
          </body>
        </body>
      </body>

      <!-- Right Arm -->
      <body name="base_link_right" pos="0 -0.3 0" childclass="piper" gravcomp="1">
        <inertial pos="-0.00979275 1.82906e-06 0.04101" quat="0.692988 -0.137524 -0.137826 0.69416" mass="0.162549" diaginertia="0.000269445 0.000227478 0.000221437" />
        <body name="link1_right" pos="0 0 0.123" quat="0.707105 0 0 -0.707108" gravcomp="1">
          <inertial pos="0.00131676 0.000310289 -0.00922875" quat="0.557105 0.432155 0.377373 0.600388" mass="0.097868" diaginertia="9.25942e-05 8.3083e-05 7.69469e-05" />
          <joint name="joint1_right" axis="0 0 1" range="-2.618 2.618" />
          <body name="link2_right" quat="0.499998 0.5 -0.500002 -0.5" gravcomp="1">
            <inertial pos="0.148794 -0.00242027 0.00175155" quat="-0.0249063 0.70684 0.00803509 0.706889" mass="0.290889" diaginertia="0.00177549 0.00173142 0.00014552" />
            <joint name="joint2_right" axis="0 0 1" range="0 3.14" />
            <body name="link3_right" pos="0.28358 0.028726 0" quat="0.998726 0 0 0.0504536" gravcomp="1">
              <inertial pos="-0.0996835 0.0349477 0.000508026" quat="0.0777021 0.702287 -0.0990541 0.700674" mass="0.290848" diaginertia="0.000241946 0.000222224 0.000100384" />
              <joint name="joint3_right" pos="0 0 0" axis="0 0 1" range="-2.697 0" />
              <body name="link4_right" pos="-0.24221 0.068514 0" quat="0.544767 -0.544769 -0.450809 0.450808" gravcomp="1">
                <inertial pos="0.000276465 -0.00102804 -0.00472831" quat="0.492305 0.505285 0.503294 0.499017" mass="0.127087" diaginertia="4.87057e-05 4.10595e-05 3.82001e-05" />
                <joint name="joint4_right" axis="0 0 1" range="-1.832 1.832" />
                <body name="link5_right" quat="0.707105 0.707108 0 0" gravcomp="1">
                  <inertial pos="8.82262e-05 0.0566829 -0.0019612" quat="0.507447 0.490986 0.506887 0.494466" mass="0.144711" diaginertia="0.001 0.001 0.001" />
                  <joint name="joint5_right" axis="0 0 1" range="-1.22 1.22" />
                  <body name="link6_right" pos="0 0.091 0.0014165" quat="0 0 -0.707105 -0.707108" gravcomp="1">
                    <inertial pos="0.0010312 0.0121761 0.0315481" quat="0.0230402 0.707091 0.0373344 0.70576" mass="1.2" diaginertia="0.001 0.001 0.001" />
                    <joint name="joint6_right" axis="0 0 1" range="-3.14 3.14" />
                    <site name="EE_right" pos="0.00 0.0 0.13503" euler="3.1415926 0 3.1415926" size="0.001" />
                  </body>
                </body>
              </body>
            </body>
          </body>
        </body>
      </body>
    </body>
  </worldbody>

  <actuator>
    <!-- Left Arm Actuators -->
    <position name="joint1_left" joint="joint1_left" class="piper" kp="80" kv="5" />
    <position name="joint2_left" joint="joint2_left" class="piper" kp="80" kv="5" />
    <position name="joint3_left" joint="joint3_left" class="piper" kp="80" kv="5" />
    <position name="joint4_left" joint="joint4_left" class="piper" kp="40" kv="5" />
    <position name="joint5_left" joint="joint5_left" class="piper" kp="10" kv="1.5" />
    <position name="joint6_left" joint="joint6_left" class="piper" kp="10" kv="1.5" />

    <!-- Right Arm Actuators -->
    <position name="joint1_right" joint="joint1_right" class="piper" kp="80" kv="5" />
    <position name="joint2_right" joint="joint2_right" class="piper" kp="80" kv="5" />
    <position name="joint3_right" joint="joint3_right" class="piper" kp="80" kv="5" />
    <position name="joint4_right" joint="joint4_right" class="piper" kp="40" kv="5" />
    <position name="joint5_right" joint="joint5_right" class="piper" kp="10" kv="1.5" />
    <position name="joint6_right" joint="joint6_right" class="piper" kp="10" kv="1.5" />
  </actuator>

  <keyframe>
    <key name="home" qpos="0 0 0 0 0 0 0 0 0 0 0 0" />
    <key name="standby1" qpos="0 1.57079 -1.57079 0 1.57079 0 0 1.57079 -1.57079 0 1.57079 0" />
    <key name="standby2" qpos="0 1.57079 -1.57079 0 1.57079 0 0 1.57079 -1.57079 0 1.57079 0" />
  </keyframe>

</mujoco>