<?xml version="1.0"?>
<mujoco model="atom_links">

    <body name="torso_link" pos="0 0 0" quat="1 0 0 0">
        <inertial pos="-0.0016 -0.0035 0.2190" mass="14.0858" fullinertia="0.2105 0.1880 0.1030 0.0012 0.0045 0.0008"/>
        <geom class="visualtorso" mesh="torso_link"/>

        <body name="head_yaw_link" pos="0 0 0.4177" quat="1 0 0 0">
            <inertial pos="0.0000 -0.0027 0.0383" quat="1 0 0 0" mass="0.4387" diaginertia="0.0003 0.0002 0.0002"/>
            <geom class="visualhead" pos="0 0 0" quat="1 0 0 0" mesh="head_yaw_link"/>
            <body name="head_pitch_link" pos="0 0 0" quat="1 0 0 0">
                <inertial pos="0.0337 0.0004 0.1204" quat="1 0 0 0" mass="1.3341" diaginertia="0.0067 0.007 0.0042"/>
                <geom class="visualhead" pos="0 0 0" quat="1 0 0 0" mesh="head_pitch_link"/>
            </body>
        </body>

        <body name="uidx_arm_l1_link" pos="0 0.128 0.333">
            <inertial pos="0.00709137 0.0939536 -0.105099" quat="0.991156 0.127387 0.0224075 -0.0296784" mass="3.2211" diaginertia="0.0415523 0.0411005 0.00369402"/>
            <joint name="uidx_l_arm_joint1" pos="0 0 0" axis="0 1 0" range="-2.97 2.97" actuatorfrcrange="-56 56"/>
            <geom class="visualarm" mesh="left_shoulder_pitch_link"/>
            <geom pos="0 0.078 0" quat="0.995953 0.0898785 0 0" class="visualarm" mesh="left_shoulder_roll_link"/>
            <geom pos="0 0.102169 -0.132819" quat="0.995953 0.0898785 0 0" class="visualarm" mesh="left_shoulder_yaw_link"/>
            <body name="uidx_arm_l2_link" pos="0.000441988 0.125443 -0.260719" quat="0.995953 0.0898785 0 0">
                <inertial pos="0.195998 -0.00127758 -0.00178384" quat="-0.00931975 0.705752 -0.0256131 0.707935" mass="2.6587" diaginertia="0.023073 0.0227717 0.00221977"/>
                <joint name="uidx_l_arm_joint2" pos="0 0 0" axis="0 1 0" range="-1.57 2" actuatorfrcrange="-36 36"/>
                <geom class="visualarm" mesh="left_elbow_pitch_link"/>
                <geom pos="0.1453 0 0" quat="1 0 0 0" class="visualarm" mesh="left_elbow_roll_link"/>
                <geom pos="0.19875 0 0" quat="1 0 0 0" class="visualarm" mesh="left_wrist_pitch_link"/>
                <geom pos="0.28375 0 0" quat="1 0 0 0" class="visualarm" mesh="left_wrist_yaw_link"/>
            </body>
        </body>
        <body name="uidx_arm_r1_link" pos="0 -0.128 0.333">
            <inertial pos="-0.00794308 -0.0900033 -0.105818" quat="0.992848 -0.10471 -0.0163501 -0.0549599" mass="3.2211" diaginertia="0.0413895 0.0408708 0.00373882"/>
            <joint name="uidx_r_arm_joint1" pos="0 0 0" axis="0 1 0" range="-2.97 2.97" actuatorfrcrange="-56 56"/>
            <geom class="visualarm" mesh="right_shoulder_pitch_link"/>
            <geom pos="0 -0.078 0" quat="0.995953 -0.0898785 0 0" class="visualarm" mesh="right_shoulder_roll_link"/>
            <geom pos="0 -0.102169 -0.132819" quat="0.995953 -0.0898785 0 0" class="visualarm" mesh="right_shoulder_yaw_link"/>
            <body name="uidx_arm_r2_link" pos="0.000441988 -0.125443 -0.260719" quat="0.995953 -0.0898785 0 0">
                <inertial pos="0.195993 0.00240691 0.00184219" quat="-0.0148388 0.705757 -0.00046499 0.708299" mass="2.6587" diaginertia="0.0230604 0.0227681 0.0022105"/>
                <joint name="uidx_r_arm_joint2" pos="0 0 0" axis="0 1 0" range="-1.57 2" actuatorfrcrange="-36 36"/>
                <geom class="visualarm" mesh="right_elbow_pitch_link"/>
                <geom pos="0.145294 0 0" quat="1 0 0 0" class="visualarm" mesh="right_elbow_roll_link"/>
                <geom pos="0.198744 0 0" quat="1 0 0 0" class="visualarm" mesh="right_wrist_pitch_link"/>
                <geom pos="0.283744 0 0" quat="1 0 0 0" class="visualarm" mesh="right_wrist_yaw_link"/>
            </body>
        </body>
    </body>

    <body name="leg_l1_link" pos="0 0.0745 -0.133">
        <inertial pos="0.0011 0.037 -0.0046" quat="0.121199 0.673028 0.2758 0.675484" mass="0.6084" diaginertia="0.00182702 0.00139444 0.000978541"/>
        <joint name="leg_l1_joint" pos="0 0 0" axis="0 1 0" range="-2.5656 3.0194" actuatorfrcrange="-1000 1000"/>
        <geom class="visualleg" mesh="leg_l1_link"/>
        <body name="leg_l2_link" pos="0.00283008 0.0765 -0.0248393" quat="0.998392 0 -0.0566928 0">
            <inertial pos="-0.006 -0.0003 -0.0057" quat="0.699481 -0.103571 0.103571 0.699481" mass="2.2367" diaginertia="0.00333028 0.0032 0.00296972"/>
            <joint name="leg_l2_joint" pos="0 0 0" axis="1 0 0" range="-0.2618 1.6581" actuatorfrcrange="-1000 1000"/>
            <geom class="visualleg" mesh="leg_l2_link"/>
            <body name="leg_l3_link" pos="0 -0.02 -0.065">
                <inertial pos="-0.0023 0.0113 -0.1214" quat="0.479916 0.0431402 0.00127312 0.876252" mass="5.553" diaginertia="0.0418335 0.0411911 0.0114755"/>
                <joint name="leg_l3_joint" pos="0 0 0" axis="0 0 1" range="-2.7925 2.7925" actuatorfrcrange="-1000 1000"/>
                <geom class="visualleg" mesh="leg_l3_link"/>
                <body name="leg_l4_link" pos="-0.0468661 0 -0.321339">
                    <inertial pos="-0.0125 -0.0005 -0.104" quat="0.998306 0.00153276 0.0490998 -0.0311667" mass="3.1" diaginertia="0.0190581 0.0189 0.00264192"/>
                    <joint name="leg_l4_joint" pos="0 0 0" axis="0 1 0" range="0 2.4871" actuatorfrcrange="-1000 1000"/>
                    <geom class="visualleg" mesh="leg_l4_link"/>
                    <body name="leg_l5_link" pos="-0.0319616 0 -0.333526" quat="0.998392 0 0.0566928 0">
                        <inertial pos="9.1e-05 0.000214 -0.013313" mass="0.1552" diaginertia="4.2e-05 3.7e-05 2.3e-05"/>
                        <joint name="leg_l5_joint" pos="0 0 0" axis="0 1 0" range="-0.5236 0.8727" actuatorfrcrange="-1000 1000"/>
                        <geom class="visualleg" mesh="leg_l5_link"/>
                        <body name="leg_l6_link" pos="0 0 -0.025">
                            <inertial pos="0.0127 0.0030 -0.0060" quat="0.500438 0.498859 0.500438 0.500264" mass="0.1988" diaginertia="0.0001 0.0001 0.0001"/>
                            <joint name="leg_l6_joint" pos="0 0 0" axis="1 0 0" range="-0.48 0.48" actuatorfrcrange="-1000 1000"/>
                            <geom class="visualleg" mesh="leg_l6_link"/>
                            <site name="force_sensor_left_foot" pos="0 0 0"/>
                            <site name="torque_sensor_left_foot" pos="0 0 0"/>
                        </body>
                    </body>
                </body>
            </body>
        </body>
    </body>
    <body name="leg_r1_link" pos="0 -0.0745 -0.133">
        <inertial pos="0.0011 -0.037 -0.0046" quat="-0.0756671 0.68374 -0.214397 0.693403" mass="0.6084" diaginertia="0.00174347 0.00147629 0.000980232"/>
        <joint name="leg_r1_joint" pos="0 0 0" axis="0 1 0" range="-2.5656 1.6581" actuatorfrcrange="-1000 1000"/>
        <geom class="visualleg" mesh="leg_r1_link"/>
        <body name="leg_r2_link" pos="0.00283008 -0.0765 -0.0248393" quat="0.998392 0 -0.0566928 0">
            <inertial pos="-0.0058 0.0006 -0.0062" quat="0.973249 0.229753 0 0" mass="2.2674" diaginertia="0.0034 0.0034 0.0029"/>
            <joint name="leg_r2_joint" pos="0 0 0" axis="1 0 0" range="-1.6581 0.2618" actuatorfrcrange="-1000 1000"/>
            <geom class="visualleg" mesh="leg_r2_link"/>
            <body name="leg_r3_link" pos="0 0.02 -0.065">
                <inertial pos="-0.0023 -0.0112 -0.1214" quat="0.876382 0.00272205 0.0423698 0.479741" mass="5.553" diaginertia="0.0418212 0.0411959 0.0114829"/>
                <joint name="leg_r3_joint" pos="0 0 0" axis="0 0 1" range="-2.7925 2.7925" actuatorfrcrange="-1000 1000"/>
                <geom class="visualleg" mesh="leg_r3_link"/>
                <body name="leg_r4_link" pos="-0.0468661 0 -0.321339">
                    <inertial pos="-0.0125 0.0005 -0.104" quat="0.998306 -0.00153276 0.0490998 0.0311667" mass="3.1" diaginertia="0.0190581 0.0189 0.00264192"/>
                    <joint name="leg_r4_joint" pos="0 0 0" axis="0 1 0" range="0 2.4871" actuatorfrcrange="-1000 1000"/>
                    <geom class="visualleg" mesh="leg_r4_link"/>
                    <body name="leg_r5_link" pos="-0.0319616 0 -0.333526" quat="0.998392 0 0.0566928 0">
                        <inertial pos="9.1e-05 -0.000214 -0.013313" mass="0.1552" diaginertia="4.2e-05 3.7e-05 2.3e-05"/>
                        <joint name="leg_r5_joint" pos="0 0 0" axis="0 1 0" range="-0.5236 0.8727" actuatorfrcrange="-1000 1000"/>
                        <geom class="visualleg" mesh="leg_r5_link"/>
                        <body name="leg_r6_link" pos="0 0 -0.025">
                            <inertial pos="0.0127 -0.0030 -0.0060" quat="0.500438 0.498859 0.500438 0.500264" mass="0.1988" diaginertia="0.0001 0.0001 0.0001"/>
                            <joint name="leg_r6_joint" pos="0 0 0" axis="1 0 0" range="-0.48 0.48" actuatorfrcrange="-1000 1000"/>
                            <geom class="visualleg" mesh="leg_r6_link"/>
                            <site name="force_sensor_right_foot" pos="0 0 0"/>
                            <site name="torque_sensor_right_foot" pos="0 0 0"/>
                        </body>
                    </body>
                </body>
            </body>
        </body>
    </body>

</mujoco>
