<mujoco model="piper_links">

  <geom type="cylinder" size="0.002 0.05" rgba="1 0 0 1" pos="0.05 -0.0 0." euler="0 1.57079 0" class="visual" />
  <geom type="cylinder" size="0.002 0.05" rgba="0 1 0 1" pos="0 0.05 0." euler="1.57079 0 0" class="visual" />
  <geom type="cylinder" size="0.002 0.05" rgba="0 0 1 1" pos="0 -0.0 0.05" euler="0 0 0" class="visual" />

  <body name="base_link" childclass="piper" gravcomp="1">
    <inertial pos="-0.00979275 1.82906e-06 0.04101" quat="0.692988 -0.137524 -0.137826 0.69416" mass="0.162549" diaginertia="0.000269445 0.000227478 0.000221437" />
    <geom class="visual" density="0" mesh="base_link" material="gray_mat" />
    <geom class="collision" mesh="base_link" />
    <body name="link1" pos="0 0 0.123" quat="0.707105 0 0 -0.707108" gravcomp="1">
      <site name="shoulderSite" pos="0.0 0 0.0" rgba="1 0 0 1" />

      <inertial pos="0.00131676 0.000310289 -0.00922875" quat="0.557105 0.432155 0.377373 0.600388" mass="0.097868" diaginertia="9.25942e-05 8.3083e-05 7.69469e-05" />
      <joint name="joint1" axis="0 0 1" range="-2.618 2.618" />
      <geom class="visual" density="0" mesh="link1" material="gray_mat" />
      <geom class="collision" mesh="link1" />
      <body name="link2" quat="0.499998 0.5 -0.500002 -0.5" gravcomp="1">
        <inertial pos="0.148794 -0.00242027 0.00175155" quat="-0.0249063 0.70684 0.00803509 0.706889" mass="0.290889" diaginertia="0.00177549 0.00173142 0.00014552" />
        <joint name="joint2" axis="0 0 1" range="0 3.14" />
        <geom mesh="link2_0" material="gray_mat" class="visual" />
        <geom mesh="link2_1" material="darker_gray_mat" class="visual" />
        <geom mesh="link2_2" material="darker_gray_mat" class="visual" />
        <geom mesh="link2_3" material="dark_gray_mat" class="visual" />
        <geom mesh="link2_4" material="dark_gray_mat" class="visual" />
        <geom mesh="link2_5" material="red_mat" class="visual" />
        <geom mesh="link2_6" material="dark_gray_mat" class="visual" />
        <geom mesh="link2_7" material="gray_mat" class="visual" />
        <geom mesh="link2_8" material="red_mat" class="visual" />
        <geom mesh="link2_9" material="red_mat" class="visual" />
        <geom mesh="link2_10" material="gray_mat" class="visual" />
        <geom mesh="link2_11" material="red_mat" class="visual" />
        <geom mesh="link2_12" material="red_mat" class="visual" />
        <geom mesh="link2_13" material="red_mat" class="visual" />
        <geom mesh="link2_14" material="red_mat" class="visual" />
        <geom mesh="link2_15" material="red_mat" class="visual" />
        <geom mesh="link2_16" material="red_mat" class="visual" />
        <geom mesh="link2_17" material="red_mat" class="visual" />
        <geom mesh="link2_18" material="red_mat" class="visual" />
        <geom mesh="link2_19" material="red_mat" class="visual" />
        <geom mesh="link2_20" material="red_mat" class="visual" />
        <geom mesh="link2_21" material="gray_mat" class="visual" />
        <geom mesh="link2_22" material="red_mat" class="visual" />
        <geom mesh="link2_23" material="red_mat" class="visual" />
        <geom mesh="link2_24" material="red_mat" class="visual" />
        <geom mesh="link2_25" material="dark_gray_mat" class="visual" />
        <geom mesh="link2_26" material="red_mat" class="visual" />
        <geom mesh="link2_27" material="darker_gray_mat" class="visual" />
        <geom mesh="link2_28" material="darker_gray_mat" class="visual" />
        <geom mesh="link2_29" material="darker_gray_mat" class="visual" />
        <geom mesh="link2_30" material="darker_gray_mat" class="visual" />
        <geom mesh="link2_31" material="light_medium_gray_mat" class="visual" />
        <geom mesh="link2" class="collision" />
        <body name="link3" pos="0.28358 0.028726 0" quat="0.998726 0 0 0.0504536" gravcomp="1">
          <site name="elbowSite" pos="0.0 0 0.0" rgba="1 0 0 1" />

          <inertial pos="-0.0996835 0.0349477 0.000508026" quat="0.0777021 0.702287 -0.0990541 0.700674" mass="0.290848" diaginertia="0.000241946 0.000222224 0.000100384" />
          <joint name="joint3" pos="0 0 0" axis="0 0 1" range="-2.697 0" />
          <geom mesh="link3_0" material="darker_gray_mat" class="visual" />
          <geom mesh="link3_1" material="red_mat" class="visual" />
          <geom mesh="link3_2" material="gray_mat" class="visual" />
          <geom mesh="link3_3" material="gray_mat" class="visual" />
          <geom mesh="link3_4" material="gray_mat" class="visual" />
          <geom mesh="link3_5" material="gray_mat" class="visual" />
          <geom mesh="link3_7" material="darker_gray_mat" class="visual" />
          <geom mesh="link3_8" material="white_mat" class="visual" />
          <geom mesh="link3_9" material="red_mat" class="visual" />
          <geom mesh="link3_10" material="white_mat" class="visual" />
          <geom mesh="link3_11" material="white_mat" class="visual" />
          <geom mesh="link3_12" material="white_mat" class="visual" />
          <geom mesh="link3_13" material="white_mat" class="visual" />
          <geom mesh="link3_14" material="gray_mat" class="visual" />
          <geom mesh="link3_15" material="gray_mat" class="visual" />
          <geom mesh="link3_16" material="gray_mat" class="visual" />
          <geom mesh="link3_17" material="gray_mat" class="visual" />
          <geom mesh="link3_18" material="gray_mat" class="visual" />
          <geom mesh="link3_19" material="gray_mat" class="visual" />
          <geom mesh="link3_20" material="gray_mat" class="visual" />
          <geom mesh="link3_21" material="gray_mat" class="visual" />
          <geom mesh="link3_22" material="gray_mat" class="visual" />
          <geom mesh="link3_23" material="gray_mat" class="visual" />
          <geom mesh="link3_24" material="gray_mat" class="visual" />
          <geom mesh="link3_25" material="gray_mat" class="visual" />
          <geom mesh="link3_26" material="gray_mat" class="visual" />
          <geom mesh="link3_27" material="gray_mat" class="visual" />
          <geom mesh="link3_28" material="gray_mat" class="visual" />
          <geom mesh="link3" class="collision" />
          <body name="link4" pos="-0.24221 0.068514 0" quat="0.544767 -0.544769 -0.450809 0.450808" gravcomp="1">
            <inertial pos="0.000276465 -0.00102804 -0.00472831" quat="0.492305 0.505285 0.503294 0.499017" mass="0.127087" diaginertia="4.87057e-05 4.10595e-05 3.82001e-05" />
            <joint name="joint4" axis="0 0 1" range="-1.832 1.832" />
            <geom mesh="link4_2" material="gray_mat" class="visual" />
            <geom mesh="link4_3" material="darker_gray_mat" class="visual" />
            <geom mesh="link4_4" material="gray_mat" class="visual" />
            <geom mesh="link4_5" material="gray_mat" class="visual" />
            <geom mesh="link4_6" material="gray_mat" class="visual" />
            <geom mesh="link4" class="collision" />
            <body name="link5" quat="0.707105 0.707108 0 0" gravcomp="1">
              <site name="wristSite" pos="0.0 0 0.0" rgba="1 0 0 1" />

              <inertial pos="8.82262e-05 0.0566829 -0.0019612" quat="0.507447 0.490986 0.506887 0.494466" mass="0.144711" diaginertia="0.001 0.001 0.001" />
              <!-- <joint name="joint5" axis="0 0 1" range="-1.22 1.22"/>    -->
              <joint name="joint5" axis="0 0 1" range="-1.62 1.62" />
              <geom mesh="link5_2" material="black_mat" class="visual" />
              <geom mesh="link5_3" material="black_mat" class="visual" />
              <geom mesh="link5_4" material="darker_gray_mat" class="visual" />
              <geom mesh="link5_5" material="gray_mat" class="visual" />
              <geom mesh="link5_6" material="light_gray_mat" class="visual" />
              <geom mesh="link5_7" material="gray_mat" class="visual" />
              <geom mesh="link5_8" material="gray_mat" class="visual" />
              <geom mesh="link5" class="collision" />
              <body name="link6" pos="0 0.091 0.0014165" quat="0 0 -0.707105 -0.707108" gravcomp="1">
                <inertial pos="0.0010312 0.0121761 0.0315481" quat="0.0230402 0.707091 0.0373344 0.70576" mass="1.2" diaginertia="0.001 0.001 0.001" />
                <joint name="joint6" axis="0 0 1" range="-3.14 3.14" />
                <geom quat="0.707105 0 0 0.707108" mesh="link6" material="gray_mat" class="visual" />
                <geom quat="0.707105 0 0 0.707108" mesh="link6" class="collision" />
                <body name="wrist_camera" pos="-0.15 0.001 0.08" euler="0 1.19 -1.57">
                  <geom type="mesh" mesh="wrist_camera" rgba="1 1 1 1" />
                  <body pos="0.00125 0.044 0.065" euler="-2.5 0 0">
                    <camera name="Wrist_camera" mode="fixed" resolution="1920 1080" sensorsize="5.37 4.04" focal="2.9 2.9" />
                  </body>
                </body>
                <body name="link7" pos="0 0 0.13503" quat="1.89468e-08 1.89469e-08 0.707108 0.707105" gravcomp="1">
                  <inertial pos="-0.000277778 -0.0467673 -0.00921029" quat="0.46134 0.536174 -0.553273 0.439968" mass="0.0264823" diaginertia="0.001 0.001 0.001" />
                  <joint name="joint7" axis="0 0 -1" class="finger" range="0 0.035" />
                  <geom mesh="link7" rgba="0.8 0.4 0.2 1" class="visual" />
                  <geom type="box" size=".012 .015 .0025" pos="0 -0.015 -0.0025" rgba="1 0 0 .2" class="collision" />
                  <geom type="box" size=".015 .015 .0025" pos="0 -0.045 -0.0025" rgba="0 0 1 .2" class="collision" />
                </body>
                <body name="link8" pos="0 0 0.13503" quat="1.89468e-08 -1.89469e-08 -0.707108 0.707105" gravcomp="1">
                  <inertial pos="0.000277817 0.0467674 -0.0092103" quat="0.553273 0.439968 -0.46134 0.536174" mass="0.0264822" diaginertia="0.001 0.001 0.001" />
                  <joint name="joint8" axis="0 0 1" class="finger" range="-0.035 0" />
                  <geom mesh="link8" rgba="0.8 0.4 0.2 1" class="visual" />
                  <geom type="box" size=".012 .015 .0025" pos="0 0.015 -0.0025" rgba="1 0 0 .2" class="collision" />
                  <geom type="box" size=".015 .015 .0025" pos="0 0.045 -0.0025" rgba="0 0 1 .2" class="collision" />
                </body>

                <body name="tf1" pos="0 0 0.13503" euler="3.1415926 0 3.1415926">
                  <site name="EE" rgba="0.8 0.8 0 0" size="0.001" />
                  <!-- <geom type="cylinder" size="0.002 0.05" rgba="1 0 0 1" pos="0.05 0 0" euler="0 1.57079 0" class="visual" />
                  <geom type="cylinder" size="0.002 0.05" rgba="0 1 0 1" pos="0 0.05 0" euler="1.57079 0 0" class="visual" />
                  <geom type="cylinder" size="0.002 0.05" rgba="0 0 1 1" pos="0 0 0.05" euler="0 0 0" class="visual" /> -->
                </body>

              </body>
            </body>
          </body>
        </body>
      </body>
    </body>
  </body>

</mujoco>