<mujoco model="rm_eco65_description">
  <compiler angle="radian" meshdir="../assets/"/>

  <asset>
    <mesh name="baselink" file="baselink.STL"/>
    <mesh name="Link1" file="Link1.STL"/>
    <mesh name="Link2" file="Link2.STL"/>
    <mesh name="Link3" file="Link3.STL"/>
    <mesh name="Link4" file="Link4.STL"/>
    <mesh name="Link5" file="Link5.STL"/>
    <mesh name="Link6" file="Link6.STL"/>
  </asset>

  <contact>
    <exclude body1="baselink" body2="Link1"/>
    <exclude body1="baselink" body2="Link2"/>
    <exclude body1="Link1" body2="Link2"/>
    <exclude body1="Link2" body2="Link3"/>
    <exclude body1="Link3" body2="Link4"/>
  </contact>

  <worldbody>
    <body name="baselink" pos="0.45 0.45 0.4">
      <geom type="mesh" rgba="1 1 0.9451 1" mesh="baselink"/>
      <body name="Link1" pos="0 0 0.1625">
        <inertial pos="-0.022858 -2.0784e-06 -0.013658" quat="0.422359 0.558164 0.572915 0.426419" mass="0.74247" diaginertia="0.00184837 0.00159481 0.000747401"/>
        <joint name="joint1" pos="0 0 0" axis="0 0 1" range="-3.1067 3.1067" actuatorfrcrange="-100 100"/>
        <geom type="mesh" rgba="1 1 0.9451 1" mesh="Link1"/>
        <body name="Link2" pos="-0.086 0 0" quat="0.707105 0.707108 0 0">
          <inertial pos="-1.6049e-06 0.10336 0.067332" quat="0.49284 0.507114 -0.50706 0.492782" mass="1.3502" diaginertia="0.0129426 0.012821 0.00111406"/>
          <joint name="joint2" pos="0 0 0" axis="0 0 -1" range="-3.1067 2.3562" actuatorfrcrange="-100 100"/>
          <geom type="mesh" rgba="1 1 0.9451 1" mesh="Link2"/>
          <body name="Link3" pos="0 0.26 0" quat="-2.59734e-06 0.707105 0.707108 -2.59735e-06">
            <inertial pos="0.10374 7.0495e-07 0.018599" quat="0.519814 0.479367 0.479376 0.519807" mass="1.0422" diaginertia="0.0094046 0.00930383 0.000785521"/>
            <joint name="joint3" pos="0 0 0" axis="0 0 1" range="-2.7925 2.5307" actuatorfrcrange="-100 100"/>
            <geom type="mesh" rgba="1 1 0.9451 1" mesh="Link3"/>
            <body name="Link4" pos="0.24 0 -0.05888" quat="0.707105 0 0 0.707108">
              <inertial pos="-0.0069819 -0.016328 0.0067416" quat="0.446544 0.894762 -6.23183e-05 5.65167e-06" mass="0.27383" diaginertia="0.00024751 0.000214431 0.000154999"/>
              <joint name="joint4" pos="0 0 0" axis="0 0 1" range="-3.1067 3.1067" actuatorfrcrange="-100 100"/>
              <geom type="mesh" rgba="1 1 0.9451 1" mesh="Link4"/>
              <body name="Link5" pos="0.00040486 -0.10983 0" quat="0.707105 0.707108 0 0">
                <inertial pos="-0.00040425 0.0066328 -0.012475" quat="0.446544 0.894762 -6.23183e-05 5.65167e-06" mass="0.27794" diaginertia="0.00024751 0.000214431 0.000154999"/>
                <joint name="joint5" pos="0 0 0" axis="0 0 1" range="-3.1067 3.1067" actuatorfrcrange="-100 100"/>
                <geom type="mesh" rgba="0.29804 0.28627 0.28235 1" mesh="Link5"/>
                <body name="Link6" pos="0 0.0795 0" quat="0.707105 -0.707108 0 0">
                  <inertial pos="0.00095587 -0.0013555 -0.010297" quat="0.594994 0.390437 -0.592979 0.37672" mass="0.033025" diaginertia="2.04079e-05 1.33215e-05 1.12267e-05"/>
                  <joint name="joint6" pos="0 0 0" axis="0 0 1" range="-6.2832 6.2832" actuatorfrcrange="-100 100"/>
                  <geom type="mesh" rgba="1 1 0.9451 1" mesh="Link6"/>
                  <site name="leftEE" pos="0.0 0 0" euler="0 0 0" rgba="1 0 0 1" size="0.01"/>
                </body>
              </body>
            </body>
          </body>
        </body>
      </body>
    </body>
  </worldbody>

  <actuator>
    <position name="lj1" joint="joint1" kp="80" dampratio="0.8"/>
    <position name="lj2" joint="joint2" kp="120" dampratio="0.8"/>
    <position name="lj3" joint="joint3" kp="100" dampratio="0.8"/>
    <position name="lj4" joint="joint4" kp="100" dampratio="0.8"/>
    <position name="lj5" joint="joint5" kp="80" dampratio="0.8"/>
    <position name="lj6" joint="joint6" kp="5" dampratio="0.8"/>
  </actuator>

  <sensor>
    <framepos name="eePos" objtype="site" objname="leftEE"/>
    <framequat name="eeQuat" objtype="site" objname="leftEE"/>
    <framelinvel name="eeLinVel" objtype="site" objname="leftEE"/>
    <frameangvel name="eeAngVel" objtype="site" objname="leftEE"/>
    <gyro name="eeGyro" site="leftEE"/>
    <accelerometer name="eeAcc" site="leftEE"/>
  </sensor>
</mujoco>
