<mujoco model="fr3">
  <compiler angle="radian" />

  <default>
    <default class="fr3">
      <joint armature="0.1" damping="1" />
      <position inheritrange="1" />
      <default class="visual">
        <geom type="mesh" group="2" contype="0" conaffinity="0" />
      </default>
      <site size="0.001" rgba="0.5 0.5 0.5 0.3" group="4" />
    </default>
  </default>

  <asset>
    <material name="white" rgba="1 1 1 1" />
    <material name="off_white" rgba="0.901961 0.921569 0.929412 1" />
    <material name="black" rgba="0.2 0.2 0.2 1" />
    <material name="metal" rgba="0.58 0.58 0.58 1" />
    <material name="silicone" rgba="0.1882 0.1882 0.1882 1" />
    <material name="gray" rgba="0.863156 0.863156 0.863157 1" />
    <material name="orange" rgba="1.0 0.5 0.0 1" />
    <material name="red" rgba="1 0.072272 0.039546 1" />
    <material name="yellow" rgba="1.0 1.0 0.0 1" />
    <material name="green" rgba="0.0 1.0 0.0 1" />
    <material name="blue" rgba="0.0 0.0 1.0 1" />

    <material name="button_green" rgba="0.102241 0.571125 0.102242 1" />
    <material name="button_red" rgba="0.520996 0.008023 0.013702 1" />
    <material name="button_blue" rgba="0.024157 0.445201 0.737911 1" />
  </asset>

  <worldbody>

    <body name="base" childclass="fr3">
      <body name="fr3_link0">
        <body name="fr3_link1" pos="0 0 0.333">
          <site name="shoulderSite" pos="0.0 0 0.0" rgba="1 0 0 1" />

          <inertial pos="4.128e-07 -0.0181251 -0.0386036" quat="0.999901 0.0021545 0.00429041 0.0132325" mass="2.92747" diaginertia="0.0186043 0.0181194 0.00538716" />
          <joint name="fr3_joint1" axis="0 0 1" range="-2.7437 2.7437" actuatorfrcrange="-87 87" />
          <body name="fr3_link2" quat="1 -1 0 0">
            <inertial pos="0.00318289 -0.0743222 0.00881461" quat="0.356855 0.680818 -0.434812 0.469126" mass="2.93554" diaginertia="0.0299291 0.0299291 0.0299291" />
            <joint name="fr3_joint2" axis="0 0 1" range="-1.7837 1.7837" actuatorfrcrange="-87 87" />
            <body name="fr3_link3" pos="0 -0.316 0" quat="1 1 0 0">
              <inertial pos="0.0407016 -0.00482006 -0.0289731" quat="0.950032 -0.148357 0.229935 0.150201" mass="2.2449" diaginertia="0.0140109 0.0140109 0.0140109" />
              <joint name="fr3_joint3" axis="0 0 1" range="-2.9007 2.9007" actuatorfrcrange="-87 87" />
              <body name="fr3_link4" pos="0.0825 0 0" quat="1 1 0 0">
                <site name="elbowSite" pos="0.0 0 0.0" rgba="1 0 0 1" />

                <inertial pos="-0.0459101 0.0630493 -0.00851879" quat="0.23761 0.892458 -0.00078702 0.383484" mass="2.6156" diaginertia="0.0206104 0.0206104 0.0206104" />
                <joint name="fr3_joint4" axis="0 0 1" range="-3.0421 -0.1518" actuatorfrcrange="-87 87" />
                <body name="fr3_link5" pos="-0.0825 0.384 0" quat="1 -1 0 0">
                  <inertial pos="-0.00160396 0.0292536 -0.0972966" quat="0.922285 0.098826 0.0982562 -0.360514" mass="2.32712" diaginertia="0.0182879 0.0182879 0.0182879" />
                  <joint name="fr3_joint5" axis="0 0 1" range="-2.8065 2.8065" actuatorfrcrange="-12 12" />
                  <body name="fr3_link6" quat="1 1 0 0">
                    <site name="wristSite" pos="0.0 0 0.0" rgba="1 0 0 1" />

                    <inertial pos="0.0597131 -0.0410295 -0.0101693" quat="0.593933 0.525442 0.520644 0.316361" mass="1.81704" diaginertia="0.00483538 0.00483538 0.00483538" />
                    <joint name="fr3_joint6" axis="0 0 1" range="0.5445 4.5169" actuatorfrcrange="-12 12" />
                    <body name="fr3_link7" pos="0.088 0 0" quat="1 1 0 0">
                      <inertial pos="0.00452258 0.00862619 -0.0161633" quat="0.120255 0.394761 -0.799132 0.437139" mass="0.627143" diaginertia="3.076e-07 3.076e-07 3.076e-07" />
                      <joint name="fr3_joint7" axis="0 0 1" range="-3.0159 3.0159" actuatorfrcrange="-12 12" />

                      <site name="EE" pos="0.0 0 0.2095" euler="3.1415926 0 0.7853981" rgba="1 0 0 1" />

                    </body>
                  </body>
                </body>
              </body>
            </body>
          </body>
        </body>
      </body>
    </body>
  </worldbody>

  <actuator>
    <position class="fr3" name="lj1" joint="fr3_joint1" kp="4500" kv="450" />
    <position class="fr3" name="lj2" joint="fr3_joint2" kp="4500" kv="450" />
    <position class="fr3" name="lj3" joint="fr3_joint3" kp="3500" kv="350" />
    <position class="fr3" name="lj4" joint="fr3_joint4" kp="3500" kv="350" />
    <position class="fr3" name="lj5" joint="fr3_joint5" kp="2000" kv="200" />
    <position class="fr3" name="lj6" joint="fr3_joint6" kp="2000" kv="200" />
    <position class="fr3" name="lj7" joint="fr3_joint7" kp="2000" kv="200" />
  </actuator>

  <keyframe>
    <key name="home" qpos="0 0 0 0 0 0 0" />
    <key name="standby1" qpos="0 0 0 -1.57079 0 1.57079 0.7853" />
    <key name="standby2" qpos="0 0 0 -1.57079 0 1.57079 0.7853" />
  </keyframe>

</mujoco>